Workbook
Name Slicer_Age_Group: #N/A
Name Slicer_Attendance_Rate_Percent: #N/A
Name Slicer_Attrition_Rate1: #N/A
Name Slicer_Department_name: #N/A
Name Slicer_Job_Title: #N/A
Name Slicer_Location_name: #N/A
Name Slicer_Performance_Level: #N/A
Name Slicer_Salary_Band: #N/A
Name Slicer_TOTAL_EMPLOYEES: #N/A

Sheet Departments
A1: Department_ID | B1: Department_Name
A2: D01 | B2: Sales
A3: D02 | B3: HR
A4: D03 | B4: Finance
A5: D04 | B5: IT
A6: D05 | B6: Marketing
A7: D06 | B7: Operations
A8: D07 | B8: Customer Support

Sheet Sheet1
A3: Row Labels | B3: Count of Gender
A4: D01 | B4: 360
A5: D02 | B5: 337
A6: D03 | B6: 342
A7: D04 | B7: 375
A8: D05 | B8: 367
A9: D06 | B9: 369
A10: D07 | B10: 350
A11: (blank)
A12: Grand Total | B12: 2500

Sheet Employee
A1: Employee_ID | B1: Employee_Name | C1: Department_name | D1: Department_ID | E1: Location_name | F1: Location_ID | G1: Job_Title | H1: Salary_Band | I1: Employment_Type | J1: Gender | K1: Age_Group | L1: Hire_Date | M1: Attendance_Rate_Percent | N1: Performance_Score | O1: Performance_Level | P1: Review_Status | Q1: Manager_Rating | R1: Training_Hours | S1: Attrition_status | T1: Exit_Date | U1: Manager_ID
A2: 303520 | B2: Zaid Al Falasi | C2: =_xlfn.XLOOKUP(D2,Departments!$A$2:$A$8,Departments!$B$2:$B$8) -> Operations | D2: D06 | E2: {=_xlfn.XLOOKUP(F2,Locations!$A$2:$A$6,Locations!$B$2:$B$6,NOT FOUND)} -> Dubai | F2: L01 | G2: Accountant | H2: Band 2 | I2: Full-Time | J2: Male | K2: 30-39 | L2: 2021-03-16 | M2: 78.51 | N2: 68 | O2: Low | P2: Not Due | S2: Active
A3: 303521 | B3: Hassan Shaikh | C3: =_xlfn.XLOOKUP(D3,Departments!$A$2:$A$8,Departments!$B$2:$B$8) -> Sales | D3: D01 | E3: {=_xlfn.XLOOKUP(F3,Locations!$A$2:$A$6,Locations!$B$2:$B$6,NOT FOUND)} -> Ajman | F3: L04 | G3: Marketing Specialist | H3: Band 4 | I3: Part-Time | J3: Female | K3: 30-39 | L3: 2024-02-19 | M3: 75.63 | N3: 67 | O3: Low | P3: Completed | Q3: 2 | S3: Active
A4: 303522 | B4: Omar Al Falasi | C4: =_xlfn.XLOOKUP(D4,Departments!$A$2:$A$8,Departments!$B$2:$B$8) -> HR | D4: D02 | E4: {=_xlfn.XLOOKUP(F4,Locations!$A$2:$A$6,Locations!$B$2:$B$6,NOT FOUND)} -> Sharjah | F4: L03 | G4: Sales Manager | H4: Band 4 | I4: Contract | J4: Female | K4: 30-39 | L4: 2022-08-28 | M4: 82.67 | N4: 71 | O4: Low | P4: Not Due | R4: 9 | S4: Active
A5: 303523 | B5: Imran Shaikh | C5: =_xlfn.XLOOKUP(D5,Departments!$A$2:$A$8,Departments!$B$2:$B$8) -> Sales | D5: D01 | E5: {=_xlfn.XLOOKUP(F5,Locations!$A$2:$A$6,Locations!$B$2:$B$6,NOT FOUND)} -> Al Ain | F5: L05 | G5: HR Manager | H5: Band 4 | I5: Full-Time | J5: Female | K5: 30-39 | L5: 2021-03-29 | M5: 98.48 | N5: 92 | O5: High | P5: Pending | R5: 23 | S5: Active
A6: 303524 | B6: Layla Al Falasi | C6: =_xlfn.XLOOKUP(D6,Departments!$A$2:$A$8,Departments!$B$2:$B$8) -> Customer Support | D6: D07 | E6: {=_xlfn.XLOOKUP(F6,Locations!$A$2:$A$6,Locations!$B$2:$B$6,NOT FOUND)} -> Dubai | F6: L01 | G6: Sales Executive | H6: Band 4 | I6: Full-Time | J6: Female | K6: 20-29 | L6: 2023-02-20 | M6: 75.03 | N6: 59 | O6: Average | P6: Completed | Q6: 5 | R6: 13 | S6: Resigned | T6: 2024-12-27
A7: 303525 | B7: Ali Farooq | C7: =_xlfn.XLOOKUP(D7,Departments!$A$2:$A$8,Departments!$B$2:$B$8) -> Marketing | D7: D05 | E7: {=_xlfn.XLOOKUP(F7,Locations!$A$2:$A$6,Locations!$B$2:$B$6,NOT FOUND)} -> Abu Dhabi | F7: L02 | G7: HR Executive | H7: Band 3 | I7: Part-Time | J7: Male | K7: 50+ | L7: 2023-04-29 | M7: 78.82 | N7: 78 | O7: Average | P7: Pending | R7: 16 | S7: Resigned | T7: 2024-01-03
A8: 303526 | B8: Samir Khan | C8: =_xlfn.XLOOKUP(D8,Departments!$A$2:$A$8,Departments!$B$2:$B$8) -> Marketing | D8: D05 | E8: {=_xlfn.XLOOKUP(F8,Locations!$A$2:$A$6,Locations!$B$2:$B$6,NOT FOUND)} -> Sharjah | F8: L03 | G8: Operations Coordinator | H8: Band 3 | I8: Part-Time | J8: Female | K8: 40-49 | L8: 2023-12-13 | M8: 77.07 | N8: 52 | O8: Low | P8: Completed | Q8: 4 | R8: 18 | S8: Active
A9: 303527 | B9: Omar Menon | C9: =_xlfn.XLOOKUP(D9,Departments!$A$2:$A$8,Departments!$B$2:$B$8) -> Finance | D9: D03 | E9: {=_xlfn.XLOOKUP(F9,Locations!$A$2:$A$6,Locations!$B$2:$B$6,NOT FOUND)} -> Dubai | F9: L01 | G9: Software Engineer | H9: Band 3 | I9: Full-Time | J9: Male | K9: 50+ | L9: 2021-07-13 | M9: 91.05 | N9: 73 | O9: Average | P9: Completed | Q9: 4 | R9: 8 | S9: Active
A10: 303528 | B10: Rashid Hussain | C10: =_xlfn.XLOOKUP(D10,Departments!$A$2:$A$8,Departments!$B$2:$B$8) -> Finance | D10: D03 | E10: {=_xlfn.XLOOKUP(F10,Locations!$A$2:$A$6,Locations!$B$2:$B$6,NOT FOUND)} -> Ajman | F10: L04 | G10: HR Manager | H10: Band 1 | I10: Contract | J10: Female | K10: 40-49 | L10: 2024-01-01 | M10: 92.94 | N10: 85 | O10: High | P10: Pending | R10: 18 | S10: Resigned | T10: 2026-08-07
A11: 303529 | B11: Ahmed Gupta | C11: =_xlfn.XLOOKUP(D11,Departments!$A$2:$A$8,Departments!$B$2:$B$8) -> IT | D11: D04 | E11: {=_xlfn.XLOOKUP(F11,Locations!$A$2:$A$6,Locations!$B$2:$B$6,NOT FOUND)} -> Ajman | F11: L04 | G11: HR Executive | H11: Band 1 | I11: Full-Time | J11: Female | K11: 40-49 | L11: 2023-10-07 | M11: 76.71 | N11: 62 | O11: Average | P11: Completed | Q11: 3 | R11: 32 | S11: Active
A12: 303530 | B12: Karim Aziz | C12: =_xlfn.XLOOKUP(D12,Departments!$A$2:$A$8,Departments!$B$2:$B$8) -> IT | D12: D04 | E12: {=_xlfn.XLOOKUP(F12,Locations!$A$2:$A$6,Locations!$B$2:$B$6,NOT FOUND)} -> Sharjah | F12: L03 | G12: HR Manager | H12: Band 3 | I12: Part-Time | J12: Male | K12: 20-29 | L12: 2022-04-04 | M12: 90.1 | N12: 88 | O12: Average | P12: Completed | Q12: 3 | S12: Active | U12: 303525
A13: 303531 | B13: Ali Hussain | C13: =_xlfn.XLOOKUP(D13,Departments!$A$2:$A$8,Departments!$B$2:$B$8) -> IT | D13: D04 | E13: {=_xlfn.XLOOKUP(F13,Locations!$A$2:$A$6,Locations!$B$2:$B$6,NOT FOUND)} -> Abu Dhabi | F13: L02 | G13: HR Manager | H13: Band 1 | I13: Contract | J13: Female | K13: 40-49 | L13: 2024-03-23 | M13: 80.31 | N13: 71 | O13: Low | P13: Completed | Q13: 2 | R13: 24 | S13: Resigned | T13: 2025-09-24 | U13: 303527
A14: 303532 | B14: Ahmed Menon | C14: =_xlfn.XLOOKUP(D14,Departments!$A$2:$A$8,Departments!$B$2:$B$8) -> Sales | D14: D01 | E14: {=_xlfn.XLOOKUP(F14,Locations!$A$2:$A$6,Locations!$B$2:$B$6,NOT FOUND)} -> Dubai | F14: L01 | G14: HR Manager | H14: Band 3 | I14: Full-Time | J14: Male | K14: 40-49 | L14: 2023-08-13 | M14: 85.08 | N14: 87 | O14: High | P14: Completed | Q14: 5 | R14: 15 | S14: Active | U14: 303526
A15: 303533 | B15: Karim Al Nuaimi | C15: =_xlfn.XLOOKUP(D15,Departments!$A$2:$A$8,Departments!$B$2:$B$8) -> HR | D15: D02 | E15: {=_xlfn.XLOOKUP(F15,Locations!$A$2:$A$6,Locations!$B$2:$B$6,NOT FOUND)} -> Al Ain | F15: L05 | G15: Sales Executive | H15: Band 1 | I15: Full-Time | J15: Male | K15: 50+ | L15: 2023-02-25 | M15: 79.62 | N15: 79 | O15: Low | P15: Completed | Q15: 2 | S15: Active | U15: 303525
A16: 303534 | B16: Karim Al Falasi | C16: =_xlfn.XLOOKUP(D16,Departments!$A$2:$A$8,Departments!$B$2:$B$8) -> HR | D16: D02 | E16: {=_xlfn.XLOOKUP(F16,Locations!$A$2:$A$6,Locations!$B$2:$B$6,NOT FOUND)} -> Sharjah | F16: L03 | G16: HR Executive | H16: Band 3 | I16: Contract | J16: Female | K16: 50+ | L16: 2022-12-21 | M16: 99.87 | N16: 96 | O16: Average | P16: Pending | R16: 20 | S16: Active | U16: 303526
A17: 303535 | B17: Imran Shaikh | C17: =_xlfn.XLOOKUP(D17,Departments!$A$2:$A$8,Departments!$B$2:$B$8) -> Finance | D17: D03 | E17: {=_xlfn.XLOOKUP(F17,Locations!$A$2:$A$6,Locations!$B$2:$B$6,NOT FOUND)} -> Al Ain | F17: L05 | G17: Sales Manager | H17: Band 2 | I17: Part-Time | J17: Female | K17: 30-39 | L17: 2021-09-14 | M17: 97.83 | N17: 88 | O17: High | P17: Completed | Q17: 4 | R17: 24 | S17: Active | U17: 303534
A18: 303536 | B18: Mohammed Gupta | C18: =_xlfn.XLOOKUP(D18,Departments!$A$2:$A$8,Departments!$B$2:$B$8) -> IT | D18: D04 | E18: {=_xlfn.XLOOKUP(F18,Locations!$A$2:$A$6,Locations!$B$2:$B$6,NOT FOUND)} -> Abu Dhabi | F18: L02 | G18: Sales Executive | H18: Band 3 | I18: Full-Time | J18: Male | K18: 30-39 | L18: 2024-03-23 | M18: 81.35 | N18: 74 | O18: Low | P18: Completed | Q18: 2 | R18: 26 | S18: Active | U18: 303530
A19: 303537 | B19: Layla Fernandez | C19: =_xlfn.XLOOKUP(D19,Departments!$A$2:$A$8,Departments!$B$2:$B$8) -> Finance | D19: D03 | E19: {=_xlfn.XLOOKUP(F19,Locations!$A$2:$A$6,Locations!$B$2:$B$6,NOT FOUND)} -> Al Ain | F19: L05 | G19: Marketing Specialist | H19: Band 2 | I19: Part-Time | J19: Female | K19: 20-29 | L19: 2022-08-29 | M19: 87.99 | N19: 71 | O19: High | P19: Completed | Q19: 5 | R19: 31 | S19: Resigned | T19: 2023-11-25 | U19: 303529
A20: 303538 | B20: Samir Nair | C20: =_xlfn.XLOOKUP(D20,Departments!$A$2:$A$8,Departments!$B$2:$B$8) -> Operations | D20: D06 | E20: {=_xlfn.XLOOKUP(F20,Locations!$A$2:$A$6,Locations!$B$2:$B$6,NOT FOUND)} -> Abu Dhabi | F20: L02 | G20: HR Manager | H20: Band 2 | I20: Full-Time | J20: Male | K20: 50+ | L20: 2021-12-17 | M20: 76.15 | N20: 75 | O20: Average | P20: Not Due | R20: 18 | S20: Resigned | T20: 2023-07-27 | U20: 303523
A21: 303539 | B21: Zaid Hussain | C21: =_xlfn.XLOOKUP(D21,Departments!$A$2:$A$8,Departments!$B$2:$B$8) -> Customer Support | D21: D07 | E21: {=_xlfn.XLOOKUP(F21,Locations!$A$2:$A$6,Locations!$B$2:$B$6,NOT FOUND)} -> Dubai | F21: L01 | G21: Customer Support Agent | H21: Band 4 | I21: Contract | J21: Male | K21: 20-29 | L21: 2022-12-09 | M21: 98.33 | N21: 90 | O21: High | P21: Pending | R21: 34 | S21: Resigned | T21: 2025-05-31 | U21: 303530
A22: 303540 | B22: Khalid Farooq | C22: =_xlfn.XLOOKUP(D22,Departments!$A$2:$A$8,Departments!$B$2:$B$8) -> IT | D22: D04 | E22: {=_xlfn.XLOOKUP(F22,Locations!$A$2:$A$6,Locations!$B$2:$B$6,NOT FOUND)} -> Sharjah | F22: L03 | G22: Accountant | H22: Band 3 | I22: Part-Time | J22: Male | K22: 40-49 | L22: 2024-02-21 | M22: 97.22 | N22: 94 | O22: High | P22: Completed | Q22: 5 | R22: 30 | S22: Active | U22: 303534
A23: 303541 | B23: Samir Al Nuaimi | C23: =_xlfn.XLOOKUP(D23,Departments!$A$2:$A$8,Departments!$B$2:$B$8) -> Marketing | D23: D05 | E23: {=_xlfn.XLOOKUP(F23,Locations!$A$2:$A$6,Locations!$B$2:$B$6,NOT FOUND)} -> Ajman | F23: L04 | G23: Finance Analyst | H23: Band 1 | I23: Contract | J23: Female | K23: 20-29 | L23: 2022-07-11 | M23: 79.79 | N23: 74 | O23: Low | P23: Pending | R23: 18 | S23: Active | U23: 303521
A24: 303542 | B24: Nadia Shaikh | C24: =_xlfn.XLOOKUP(D24,Departments!$A$2:$A$8,Departments!$B$2:$B$8) -> HR | D24: D02 | E24: {=_xlfn.XLOOKUP(F24,Locations!$A$2:$A$6,Locations!$B$2:$B$6,NOT FOUND)} -> Dubai | F24: L01 | G24: Sales Manager | H24: Band 1 | I24: Contract | J24: Male | K24: 20-29 | L24: 2021-05-13 | M24: 91.65 | N24: 73 | O24: High | P24: Completed | Q24: 5 | R24: 38 | S24: Active | U24: 303522
A25: 303543 | B25: Yusuf Joseph | C25: =_xlfn.XLOOKUP(D25,Departments!$A$2:$A$8,Departments!$B$2:$B$8) -> HR | D25: D02 | E25: {=_xlfn.XLOOKUP(F25,Locations!$A$2:$A$6,Locations!$B$2:$B$6,NOT FOUND)} -> Al Ain | F25: L05 | G25: Customer Support Agent | H25: Band 4 | I25: Part-Time | J25: Female | K25: 40-49 | L25: 2023-05-16 | M25: 82.84 | N25: 57 | O25: Average | P25: Pending | R25: 7 | S25: Active | U25: 303538
A26: 303544 | B26: Noor Fernandez | C26: =_xlfn.XLOOKUP(D26,Departments!$A$2:$A$8,Departments!$B$2:$B$8) -> Operations | D26: D06 | E26: {=_xlfn.XLOOKUP(F26,Locations!$A$2:$A$6,Locations!$B$2:$B$6,NOT FOUND)} -> Al Ain | F26: L05 | G26: HR Executive | H26: Band 2 | I26: Contract | J26: Male | K26: 20-29 | L26: 2023-01-12 | M26: 92.25 | N26: 73 | O26: Average | P26: Pending | R26: 11 | S26: Active | U26: 303525
A27: 303545 | B27: Samir Aziz | C27: =_xlfn.XLOOKUP(D27,Departments!$A$2:$A$8,Departments!$B$2:$B$8) -> Operations | D27: D06 | E27: {=_xlfn.XLOOKUP(F27,Locations!$A$2:$A$6,Locations!$B$2:$B$6,NOT FOUND)} -> Al Ain | F27: L05 | G27: Software Engineer | H27: Band 4 | I27: Contract | J27: Female | K27: 40-49 | L27: 2024-01-17 | M27: 76.69 | N27: 70 | O27: Average | P27: Pending | R27: 25 | S27: Active | U27: 303534
A28: 303546 | B28: Hassan Al Falasi | C28: =_xlfn.XLOOKUP(D28,Departments!$A$2:$A$8,Departments!$B$2:$B$8) -> Marketing | D28: D05 | E28: {=_xlfn.XLOOKUP(F28,Locations!$A$2:$A$6,Locations!$B$2:$B$6,NOT FOUND)} -> Ajman | F28: L04 | G28: Sales Executive | H28: Band 4 | I28: Part-Time | J28: Male | K28: 40-49 | L28: 2021-07-06 | M28: 78.33 | N28: 52 | O28: Low | P28: Completed | Q28: 2 | R28: 35 | S28: Active | U28: 303543
A29: 303547 | B29: Layla D'Souza | C29: =_xlfn.XLOOKUP(D29,Departments!$A$2:$A$8,Departments!$B$2:$B$8) -> Operations | D29: D06 | E29: {=_xlfn.XLOOKUP(F29,Locations!$A$2:$A$6,Locations!$B$2:$B$6,NOT FOUND)} -> Dubai | F29: L01 | G29: Accountant | H29: Band 1 | I29: Part-Time | J29: Male | K29: 50+ | L29: 2023-03-04 | M29: 93.8 | N29: 70 | O29: High | P29: Pending | R29: 17 | S29: Resigned | T29: 2024-02-04 | U29: 303542
A30: 303548 | B30: Sara Sharma | C30: =_xlfn.XLOOKUP(D30,Departments!$A$2:$A$8,Departments!$B$2:$B$8) -> Customer Support | D30: D07 | E30: {=_xlfn.XLOOKUP(F30,Locations!$A$2:$A$6,Locations!$B$2:$B$6,NOT FOUND)} -> Al Ain | F30: L05 | G30: HR Manager | H30: Band 1 | I30: Contract | J30: Female | K30: 30-39 | L30: 2024-01-05 | M30: 77.91 | N30: 79 | O30: Average | P30: Not Due | R30: 5 | S30: Active | U30: 303544
A31: 303549 | B31: Nadia Gupta | C31: =_xlfn.XLOOKUP(D31,Departments!$A$2:$A$8,Departments!$B$2:$B$8) -> IT | D31: D04 | E31: {=_xlfn.XLOOKUP(F31,Locations!$A$2:$A$6,Locations!$B$2:$B$6,NOT FOUND)} -> Ajman | F31: L04 | G31: IT Support Engineer | H31: Band 2 | I31: Part-Time | J31: Male | K31: 30-39 | L31: 2022-02-05 | M31: 98.69 | N31: 96 | O31: Average | P31: Pending | R31: 15 | S31: Resigned | T31: 2024-06-27 | U31: 303521
A32: 303550 | B32: Mohammed Fernandez | C32: =_xlfn.XLOOKUP(D32,Departments!$A$2:$A$8,Departments!$B$2:$B$8) -> HR | D32: D02 | E32: {=_xlfn.XLOOKUP(F32,Locations!$A$2:$A$6,Locations!$B$2:$B$6,NOT FOUND)} -> Abu Dhabi | F32: L02 | G32: Finance Analyst | H32: Band 2 | I32: Contract | J32: Female | K32: 40-49 | L32: 2022-01-15 | M32: 97.86 | N32: 90 | O32: Average | P32: Completed | Q32: 4 | R32: 5 | S32: Terminated | T32: 2024-04-17 | U32: 303533
A33: 303551 | B33: Khalid Khan | C33: =_xlfn.XLOOKUP(D33,Departments!$A$2:$A$8,Departments!$B$2:$B$8) -> Operations | D33: D06 | E33: {=_xlfn.XLOOKUP(F33,Locations!$A$2:$A$6,Locations!$B$2:$B$6,NOT FOUND)} -> Ajman | F33: L04 | G33: Sales Manager | H33: Band 2 | I33: Contract | J33: Male | K33: 30-39 | L33: 2021-03-26 | M33: 97 | N33: 93 | O33: Average | P33: Completed | Q33: 3 | R33: 11 | S33: Resigned | T33: 2023-09-30 | U33: 303530
A34: 303552 | B34: Ali Khan | C34: =_xlfn.XLOOKUP(D34,Departments!$A$2:$A$8,Departments!$B$2:$B$8) -> Sales | D34: D01 | E34: {=_xlfn.XLOOKUP(F34,Locations!$A$2:$A$6,Locations!$B$2:$B$6,NOT FOUND)} -> Abu Dhabi | F34: L02 | G34: Customer Support Agent | H34: Band 2 | I34: Part-Time | J34: Male | K34: 40-49 | L34: 2021-12-13 | M34: 95.88 | N34: 92 | O34: Average | P34: Pending | R34: 7 | S34: Active | U34: 303527
A35: 303553 | B35: Zaid Farooq | C35: =_xlfn.XLOOKUP(D35,Departments!$A$2:$A$8,Departments!$B$2:$B$8) -> Marketing | D35: D05 | E35: {=_xlfn.XLOOKUP(F35,Locations!$A$2:$A$6,Locations!$B$2:$B$6,NOT FOUND)} -> Abu Dhabi | F35: L02 | G35: Finance Analyst | H35: Band 2 | I35: Part-Time | J35: Female | K35: 50+ | L35: 2024-02-29 | M35: 90.91 | N35: 75 | O35: High | P35: Completed | Q35: 3 | R35: 25 | S35: Active | U35: 303523
A36: 303554 | B36: Karim Khan | C36: =_xlfn.XLOOKUP(D36,Departments!$A$2:$A$8,Departments!$B$2:$B$8) -> HR | D36: D02 | E36: {=_xlfn.XLOOKUP(F36,Locations!$A$2:$A$6,Locations!$B$2:$B$6,NOT FOUND)} -> Abu Dhabi | F36: L02 | G36: Software Engineer | H36: Band 4 | I36: Full-Time | J36: Male | K36: 20-29 | L36: 2021-11-08 | M36: 94.71 | N36: 88 | O36: High | P36: Completed | Q36: 2 | R36: 17 | S36: Active | U36: 303527
A37: 303555 | B37: Sara Patel | C37: =_xlfn.XLOOKUP(D37,Departments!$A$2:$A$8,Departments!$B$2:$B$8) -> Finance | D37: D03 | E37: {=_xlfn.XLOOKUP(F37,Locations!$A$2:$A$6,Locations!$B$2:$B$6,NOT FOUND)} -> Al Ain | F37: L05 | G37: Operations Coordinator | H37: Band 4 | I37: Contract | J37: Female | K37: 40-49 | L37: 2022-06-25 | M37: 94.17 | N37: 77 | O37: High | P37: Completed | Q37: 4 | R37: 16 | S37: Resigned | T37: 2023-10-18 | U37: 303551
A38: 303556 | B38: Bilal Al Mansoori | C38: =_xlfn.XLOOKUP(D38,Departments!$A$2:$A$8,Departments!$B$2:$B$8) -> Sales | D38: D01 | E38: {=_xlfn.XLOOKUP(F38,Locations!$A$2:$A$6,Locations!$B$2:$B$6,NOT FOUND)} -> Dubai | F38: L01 | G38: HR Manager | H38: Band 1 | I38: Contract | J38: Female | K38: 30-39 | L38: 2022-08-16 | M38: 82.13 | N38: 52 | O38: Low | P38: Not Due | R38: 19 | S38: Active | U38: 303527
A39: 303557 | B39: Omar Joseph | C39: =_xlfn.XLOOKUP(D39,Departments!$A$2:$A$8,Departments!$B$2:$B$8) -> Sales | D39: D01 | E39: {=_xlfn.XLOOKUP(F39,Locations!$A$2:$A$6,Locations!$B$2:$B$6,NOT FOUND)} -> Dubai | F39: L01 | G39: IT Support Engineer | H39: Band 1 | I39: Full-Time | J39: Female | K39: 30-39 | L39: 2023-04-09 | M39: 83.95 | N39: 51 | O39: Average | P39: Completed | Q39: 4 | R39: 30 | S39: Active | U39: 303551
A40: 303558 | B40: Imran Farooq | C40: =_xlfn.XLOOKUP(D40,Departments!$A$2:$A$8,Departments!$B$2:$B$8) -> Operations | D40: D06 | E40: {=_xlfn.XLOOKUP(F40,Locations!$A$2:$A$6,Locations!$B$2:$B$6,NOT FOUND)} -> Sharjah | F40: L03 | G40: Customer Support Agent | H40: Band 4 | I40: Full-Time | J40: Female | K40: 50+ | L40: 2023-10-15 | M40: 98.06 | N40: 89 | O40: High | P40: Completed | Q40: 3 | R40: 31 | S40: Active | U40: 303521
...

Sheet Detail1
A1: Details for Sum of Attendance_Rate_Percent - Job_Title: Sales Manager, Hire_Date: 2021-01-02
A3: Employee_ID | B3: Employee_Name | C3: Department_name | D3: Department_ID | E3: Location_name | F3: Location_ID | G3: Job_Title | H3: Salary_Band | I3: Employment_Type | J3: Gender | K3: Age_Group | L3: Hire_Date | M3: Attendance_Rate_Percent | N3: Performance_Score | O3: Performance_Level | P3: Review_Status | Q3: Manager_Rating | R3: Training_Hours | S3: Attrition_status | T3: Exit_Date | U3: Manager_ID
A4: 305737 | B4: Hassan Rahman | C4: Customer Support | D4: D07 | E4: Dubai | F4: L01 | G4: Sales Manager | H4: Band 3 | I4: Full-Time | J4: Male | K4: 20-29 | L4: 2021-01-02 | M4: 81.82 | N4: 67 | O4: Low | P4: Not Due | R4: 24 | S4: Active | U4: 304307

Sheet hr_dataanalysis
A1: Total Employees= | B1: =COUNT(Employee!A2:A2501) -> 2500
A2: Active Employees= | B2: =COUNTIF(Employee!S2:S2501,"Active") -> 1899
A3: resigned Employees = | B3: =COUNTIF(Employee!S2:S2501,"resigned") -> 480
A4: terminated employees= | B4: =COUNTIF(Employee!S2:S2501,"terminated") -> 121
A5: count males employees= | B5: =COUNTIF(Employee!J2:J2501,"male") -> 1276
A6: count female employees= | B6: =COUNTIF(Employee!J2:J2501,"female") -> 1224
A7: exited employees= | B7: =B3+B4 -> 601
A8: Attrition Rate= | B8: =B7/B1 -> 0.2404

Sheet Detail3
A3: Employee_ID | B3: Employee_Name | C3: Department_name | D3: Department_ID | E3: Location_name | F3: Location_ID | G3: Job_Title | H3: Salary_Band | I3: Employment_Type | J3: Gender | K3: Age_Group | L3: Hire_Date | M3: Attendance_Rate_Percent | N3: Performance_Score | O3: Performance_Level | P3: Review_Status | Q3: Manager_Rating | R3: Training_Hours | S3: Attrition_status | T3: Exit_Date | U3: Manager_ID
A4: 306016 | B4: Bilal Gupta | C4: Sales | D4: D01 | E4: Dubai | F4: L01 | G4: Marketing Specialist | H4: Band 2 | I4: Contract | J4: Male | K4: 30-39 | L4: 2023-05-13 | M4: 99.16 | N4: 85 | O4: High | P4: Completed | Q4: 2 | R4: 31 | S4: Active | U4: 305860
A5: 305996 | B5: Mohammed Menon | C5: Sales | D5: D01 | E5: Sharjah | F5: L03 | G5: Customer Support Manager | H5: Band 4 | I5: Contract | J5: Female | K5: 20-29 | L5: 2021-12-14 | M5: 90.86 | N5: 75 | O5: Average | P5: Completed | Q5: 2 | S5: Active | U5: 305767
A6: 303522 | B6: Omar Al Falasi | C6: HR | D6: D02 | E6: Sharjah | F6: L03 | G6: Sales Manager | H6: Band 4 | I6: Contract | J6: Female | K6: 30-39 | L6: 2022-08-28 | M6: 82.67 | N6: 71 | O6: Low | P6: Not Due | R6: 9 | S6: Active
A7: 305994 | B7: Mohammed Al Mansoori | C7: Finance | D7: D03 | E7: Dubai | F7: L01 | G7: Finance Analyst | H7: Band 1 | I7: Contract | J7: Male | K7: 50+ | L7: 2022-07-02 | M7: 88.6 | N7: 81 | O7: Average | P7: Completed | Q7: 4 | R7: 5 | S7: Active | U7: 304672
A8: 305987 | B8: Noor Sharma | C8: Operations | D8: D06 | E8: Abu Dhabi | F8: L02 | G8: Marketing Specialist | H8: Band 1 | I8: Contract | J8: Female | K8: 20-29 | L8: 2022-05-07 | M8: 77.02 | N8: 77 | O8: Average | P8: Completed | Q8: 3 | R8: 7 | S8: Active | U8: 304558
A9: 305982 | B9: Mariam Hussain | C9: Sales | D9: D01 | E9: Dubai | F9: L01 | G9: Sales Manager | H9: Band 4 | I9: Contract | J9: Male | K9: 30-39 | L9: 2022-10-16 | M9: 82.86 | N9: 64 | O9: Average | P9: Not Due | R9: 5 | S9: Active | U9: 304819
A10: 305980 | B10: Aisha Menon | C10: Sales | D10: D01 | E10: Sharjah | F10: L03 | G10: HR Manager | H10: Band 4 | I10: Contract | J10: Female | K10: 20-29 | L10: 2023-09-06 | M10: 80.29 | N10: 66 | O10: Average | P10: Completed | Q10: 2 | R10: 15 | S10: Active | U10: 303747
A11: 305972 | B11: Ahmed Fernandez | C11: IT | D11: D04 | E11: Al Ain | F11: L05 | G11: Software Engineer | H11: Band 2 | I11: Contract | J11: Male | K11: 50+ | L11: 2021-12-21 | M11: 81.72 | N11: 78 | O11: Average | P11: Completed | Q11: 4 | R11: 20 | S11: Active | U11: 304503
A12: 305963 | B12: Nadia Al Mansoori | C12: Marketing | D12: D05 | E12: Al Ain | F12: L05 | G12: Sales Manager | H12: Band 1 | I12: Contract | J12: Male | K12: 30-39 | L12: 2022-01-26 | M12: 94.75 | N12: 73 | O12: High | P12: Completed | Q12: 3 | R12: 16 | S12: Active | U12: 304902
A13: 305962 | B13: Samir Hussain | C13: Marketing | D13: D05 | E13: Sharjah | F13: L03 | G13: Customer Support Manager | H13: Band 2 | I13: Contract | J13: Female | K13: 50+ | L13: 2023-01-08 | M13: 99.37 | N13: 87 | O13: High | P13: Pending | R13: 9 | S13: Active | U13: 305615
A14: 305959 | B14: Karim Joseph | C14: Marketing | D14: D05 | E14: Abu Dhabi | F14: L02 | G14: Customer Support Manager | H14: Band 1 | I14: Contract | J14: Male | K14: 50+ | L14: 2022-03-10 | M14: 78.12 | N14: 71 | O14: Low | P14: Pending | R14: 36 | S14: Active | U14: 303958
A15: 305957 | B15: Aisha Aziz | C15: HR | D15: D02 | E15: Al Ain | F15: L05 | G15: Software Engineer | H15: Band 4 | I15: Contract | J15: Female | K15: 40-49 | L15: 2023-12-18 | M15: 89.45 | N15: 81 | O15: High | P15: Completed | Q15: 2 | R15: 11 | S15: Active | U15: 304861
A16: 305956 | B16: Imran Al Nuaimi | C16: Customer Support | D16: D07 | E16: Sharjah | F16: L03 | G16: Accountant | H16: Band 4 | I16: Contract | J16: Male | K16: 40-49 | L16: 2021-11-27 | M16: 99.99 | N16: 86 | O16: High | P16: Not Due | R16: 22 | S16: Active | U16: 305300
A17: 305950 | B17: Mariam Aziz | C17: Marketing | D17: D05 | E17: Dubai | F17: L01 | G17: Sales Executive | H17: Band 4 | I17: Contract | J17: Male | K17: 40-49 | L17: 2023-11-16 | M17: 87.29 | N17: 90 | O17: Average | P17: Completed | Q17: 4 | R17: 22 | S17: Active | U17: 304905
A18: 303534 | B18: Karim Al Falasi | C18: HR | D18: D02 | E18: Sharjah | F18: L03 | G18: HR Executive | H18: Band 3 | I18: Contract | J18: Female | K18: 50+ | L18: 2022-12-21 | M18: 99.87 | N18: 96 | O18: Average | P18: Pending | R18: 20 | S18: Active | U18: 303526
A19: 305948 | B19: Aisha Al Mansoori | C19: Marketing | D19: D05 | E19: Ajman | F19: L04 | G19: Sales Manager | H19: Band 3 | I19: Contract | J19: Female | K19: 20-29 | L19: 2021-11-18 | M19: 93.63 | N19: 78 | O19: Average | P19: Completed | Q19: 5 | R19: 14 | S19: Active | U19: 304273
A20: 305945 | B20: Yusuf Shaikh | C20: Sales | D20: D01 | E20: Dubai | F20: L01 | G20: HR Manager | H20: Band 1 | I20: Contract | J20: Female | K20: 30-39 | L20: 2022-10-03 | M20: 93.63 | N20: 90 | O20: High | P20: Completed | Q20: 4 | R20: 19 | S20: Active | U20: 305295
A21: 305939 | B21: Yusuf Menon | C21: Operations | D21: D06 | E21: Sharjah | F21: L03 | G21: Customer Support Agent | H21: Band 3 | I21: Contract | J21: Female | K21: 50+ | L21: 2022-07-16 | M21: 98.73 | N21: 92 | O21: High | P21: Pending | R21: 19 | S21: Active | U21: 303757
A22: 305938 | B22: Mohammed Farooq | C22: HR | D22: D02 | E22: Sharjah | F22: L03 | G22: Accountant | H22: Band 4 | I22: Contract | J22: Male | K22: 20-29 | L22: 2024-04-12 | M22: 85.55 | N22: 85 | O22: High | P22: Not Due | R22: 25 | S22: Active | U22: 305353
A23: 305937 | B23: Omar Hussain | C23: IT | D23: D04 | E23: Abu Dhabi | F23: L02 | G23: Customer Support Agent | H23: Band 1 | I23: Contract | J23: Male | K23: 40-49 | L23: 2023-02-21 | M23: 98.03 | N23: 98 | O23: High | P23: Pending | R23: 28 | S23: Active | U23: 305497
A24: 305923 | B24: Ali Shaikh | C24: Customer Support | D24: D07 | E24: Ajman | F24: L04 | G24: Sales Executive | H24: Band 2 | I24: Contract | J24: Female | K24: 30-39 | L24: 2024-04-05 | M24: 94.27 | N24: 89 | O24: High | P24: Pending | S24: Active | U24: 305799
A25: 303541 | B25: Samir Al Nuaimi | C25: Marketing | D25: D05 | E25: Ajman | F25: L04 | G25: Finance Analyst | H25: Band 1 | I25: Contract | J25: Female | K25: 20-29 | L25: 2022-07-11 | M25: 79.79 | N25: 74 | O25: Low | P25: Pending | R25: 18 | S25: Active | U25: 303521
A26: 303542 | B26: Nadia Shaikh | C26: HR | D26: D02 | E26: Dubai | F26: L01 | G26: Sales Manager | H26: Band 1 | I26: Contract | J26: Male | K26: 20-29 | L26: 2021-05-13 | M26: 91.65 | N26: 73 | O26: High | P26: Completed | Q26: 5 | R26: 38 | S26: Active | U26: 303522
A27: 305919 | B27: Aisha Sharma | C27: HR | D27: D02 | E27: Al Ain | F27: L05 | G27: Customer Support Agent | H27: Band 1 | I27: Contract | J27: Female | K27: 20-29 | L27: 2023-12-06 | M27: 96.77 | N27: 93 | O27: High | P27: Completed | Q27: 5 | R27: 21 | S27: Active | U27: 303816
A28: 303544 | B28: Noor Fernandez | C28: Operations | D28: D06 | E28: Al Ain | F28: L05 | G28: HR Executive | H28: Band 2 | I28: Contract | J28: Male | K28: 20-29 | L28: 2023-01-12 | M28: 92.25 | N28: 73 | O28: Average | P28: Pending | R28: 11 | S28: Active | U28: 303525
A29: 303545 | B29: Samir Aziz | C29: Operations | D29: D06 | E29: Al Ain | F29: L05 | G29: Software Engineer | H29: Band 4 | I29: Contract | J29: Female | K29: 40-49 | L29: 2024-01-17 | M29: 76.69 | N29: 70 | O29: Average | P29: Pending | R29: 25 | S29: Active | U29: 303534
A30: 305916 | B30: Layla Nair | C30: Marketing | D30: D05 | E30: Sharjah | F30: L03 | G30: Finance Analyst | H30: Band 4 | I30: Contract | J30: Male | K30: 20-29 | L30: 2023-10-20 | M30: 79.65 | N30: 62 | O30: Average | P30: Completed | Q30: 5 | R30: 40 | S30: Active | U30: 303795
A31: 305911 | B31: Sara Khan | C31: Finance | D31: D03 | E31: Ajman | F31: L04 | G31: Sales Manager | H31: Band 2 | I31: Contract | J31: Male | K31: 50+ | L31: 2021-04-24 | M31: 83.36 | N31: 50 | O31: Low | P31: Completed | Q31: 5 | R31: 31 | S31: Active | U31: 305597
A32: 303548 | B32: Sara Sharma | C32: Customer Support | D32: D07 | E32: Al Ain | F32: L05 | G32: HR Manager | H32: Band 1 | I32: Contract | J32: Female | K32: 30-39 | L32: 2024-01-05 | M32: 77.91 | N32: 79 | O32: Average | P32: Not Due | R32: 5 | S32: Active | U32: 303544
A33: 305909 | B33: Omar Khan | C33: Operations | D33: D06 | E33: Abu Dhabi | F33: L02 | G33: Marketing Specialist | H33: Band 4 | I33: Contract | J33: Female | K33: 30-39 | L33: 2022-11-14 | M33: 75.07 | N33: 67 | O33: Low | P33: Not Due | R33: 28 | S33: Active | U33: 303653
A34: 305908 | B34: Yusuf Joseph | C34: Operations | D34: D06 | E34: Abu Dhabi | F34: L02 | G34: Customer Support Agent | H34: Band 1 | I34: Contract | J34: Male | K34: 40-49 | L34: 2021-11-26 | M34: 79.83 | N34: 65 | O34: Low | P34: Completed | Q34: 4 | R34: 16 | S34: Active | U34: 305602
A35: 305905 | B35: Fatima Farooq | C35: Customer Support | D35: D07 | E35: Ajman | F35: L04 | G35: Sales Executive | H35: Band 1 | I35: Contract | J35: Male | K35: 30-39 | L35: 2023-10-14 | M35: 88.38 | N35: 70 | O35: High | P35: Not Due | R35: 18 | S35: Active | U35: 303525
A36: 305901 | B36: Imran Nair | C36: Sales | D36: D01 | E36: Al Ain | F36: L05 | G36: HR Executive | H36: Band 3 | I36: Contract | J36: Male | K36: 50+ | L36: 2021-04-18 | M36: 80.35 | N36: 63 | O36: Average | P36: Completed | Q36: 2 | R36: 13 | S36: Active | U36: 303970
A37: 305900 | B37: Aisha Rahman | C37: Marketing | D37: D05 | E37: Dubai | F37: L01 | G37: Marketing Specialist | H37: Band 1 | I37: Contract | J37: Male | K37: 20-29 | L37: 2024-01-08 | M37: 97.11 | N37: 85 | O37: High | P37: Completed | Q37: 4 | R37: 15 | S37: Active | U37: 304071
A38: 305888 | B38: Sara Patel | C38: Customer Support | D38: D07 | E38: Abu Dhabi | F38: L02 | G38: Accountant | H38: Band 4 | I38: Contract | J38: Female | K38: 50+ | L38: 2023-01-16 | M38: 81.58 | N38: 54 | O38: Average | P38: Completed | Q38: 3 | R38: 8 | S38: Active | U38: 304781
A39: 305883 | B39: Ahmed Sharma | C39: IT | D39: D04 | E39: Dubai | F39: L01 | G39: Accountant | H39: Band 4 | I39: Contract | J39: Female | K39: 40-49 | L39: 2021-09-02 | M39: 80.61 | N39: 63 | O39: Low | P39: Completed | Q39: 3 | R39: 38 | S39: Active | U39: 305166
A40: 303556 | B40: Bilal Al Mansoori | C40: Sales | D40: D01 | E40: Dubai | F40: L01 | G40: HR Manager | H40: Band 1 | I40: Contract | J40: Female | K40: 30-39 | L40: 2022-08-16 | M40: 82.13 | N40: 52 | O40: Low | P40: Not Due | R40: 19 | S40: Active | U40: 303527
A41: 305880 | B41: Mariam Joseph | C41: Operations | D41: D06 | E41: Al Ain | F41: L05 | G41: HR Manager | H41: Band 3 | I41: Contract | J41: Male | K41: 30-39 | L41: 2021-07-24 | M41: 83.56 | N41: 57 | O41: Low | P41: Completed | Q41: 2 | R41: 16 | S41: Active | U41: 304569
A42: 305878 | B42: Aisha Menon | C42: Marketing | D42: D05 | E42: Al Ain | F42: L05 | G42: HR Executive | H42: Band 4 | I42: Contract | J42: Female | K42: 40-49 | L42: 2024-02-15 | M42: 78.52 | N42: 54 | O42: Low | P42: Completed | Q42: 4 | R42: 25 | S42: Active | U42: 304113
...

Sheet DEPARTMENT WISE ATTRITION RATE
A1: DEPARTMENT NAME | B1: TOTAL EMPLOYEES | C1: Resigned | D1: Terminated | E1: Attrition Rate
A2: HR | B2: =COUNTIF(Employee!C2:C2501,A2) -> 337 | C2: =COUNTIFS(Employee!$C$2:$C$2501,A2,Employee!$S$2:$S$2501,"Resigned") -> 60 | D2: =COUNTIFS(Employee!$C$2:$C$2501,A2,Employee!$S$2:$S$2501,"Terminated") -> 23 | E2: =(C2+D2)/B2 -> 0.2462908
A3: Sales | B3: =COUNTIF(Employee!C3:C2502,A3) -> 360 | C3: =COUNTIFS(Employee!$C$2:$C$2501,A3,Employee!$S$2:$S$2501,"Resigned") -> 76 | D3: =COUNTIFS(Employee!$C$2:$C$2501,A3,Employee!$S$2:$S$2501,"Terminated") -> 24 | E3: =(C3+D3)/B3 -> 0.27777778
A4: Marketing | B4: =COUNTIF(Employee!C4:C2503,A4) -> 367 | C4: =COUNTIFS(Employee!$C$2:$C$2501,A4,Employee!$S$2:$S$2501,"Resigned") -> 73 | D4: =COUNTIFS(Employee!$C$2:$C$2501,A4,Employee!$S$2:$S$2501,"Terminated") -> 10 | E4: =(C4+D4)/B4 -> 0.22615804
A5: Finance | B5: =COUNTIF(Employee!C5:C2504,A5) -> 342 | C5: =COUNTIFS(Employee!$C$2:$C$2501,A5,Employee!$S$2:$S$2501,"Resigned") -> 69 | D5: =COUNTIFS(Employee!$C$2:$C$2501,A5,Employee!$S$2:$S$2501,"Terminated") -> 16 | E5: =(C5+D5)/B5 -> 0.24853801
A6: customer support | B6: =COUNTIF(Employee!C6:C2505,A6) -> 350 | C6: =COUNTIFS(Employee!$C$2:$C$2501,A6,Employee!$S$2:$S$2501,"Resigned") -> 61 | D6: =COUNTIFS(Employee!$C$2:$C$2501,A6,Employee!$S$2:$S$2501,"Terminated") -> 21 | E6: =(C6+D6)/B6 -> 0.23428571
A7: IT | B7: =COUNTIF(Employee!C7:C2506,A7) -> 375 | C7: =COUNTIFS(Employee!$C$2:$C$2501,A7,Employee!$S$2:$S$2501,"Resigned") -> 75 | D7: =COUNTIFS(Employee!$C$2:$C$2501,A7,Employee!$S$2:$S$2501,"Terminated") -> 7 | E7: =(C7+D7)/B7 -> 0.21866667
A8: Operations | B8: =COUNTIF(Employee!C8:C2507,A8) -> 368 | C8: =COUNTIFS(Employee!$C$2:$C$2501,A8,Employee!$S$2:$S$2501,"Resigned") -> 66 | D8: =COUNTIFS(Employee!$C$2:$C$2501,A8,Employee!$S$2:$S$2501,"Terminated") -> 20 | E8: =(C8+D8)/B8 -> 0.23369565
A9: Total | B9: =SUBTOTAL(109,Table5[TOTAL EMPLOYEES]) -> 2499 | C9: =SUBTOTAL(109,Table5[Resigned]) -> 480 | D9: =SUBTOTAL(109,Table5[Terminated]) -> 121 | E9: =SUBTOTAL(101,Table5[Attrition Rate]) -> 0.24077324
A14: Row Labels | B14: Sum of Attrition Rate | P14: Row Labels | Q14: Sum of Employee_ID
A15: customer support | B15: 0.23428571 | P15: Active | Q15: 578759488
A16: Finance | B16: 0.24853801 | P16: Resigned | Q16: 146280776
A17: HR | B17: 0.2462908 | P17: Terminated | Q17: 36883486
A18: IT | B18: 0.21866667 | K18: Row Labels | L18: Sum of Resigned | M18: Sum of Terminated | P18: Grand Total | Q18: 761923750
A19: Marketing | B19: 0.22615804 | K19: customer support | L19: 61 | M19: 21
A20: Operations | B20: 0.23369565 | K20: Finance | L20: 69 | M20: 16
A21: Sales | B21: 0.27777778 | K21: HR | L21: 60 | M21: 23
A22: Grand Total | B22: 1.6854127 | K22: IT | L22: 75 | M22: 7
K23: Marketing | L23: 73 | M23: 10
K24: Operations | L24: 66 | M24: 20
K25: Sales | L25: 76 | M25: 24 | P25: Row Labels | Q25: Sum of Attendance_Rate_Percent
K26: Grand Total | L26: 480 | M26: 121 | P26: Active | Q26: 166118.08
P27: Resigned | Q27: 42205.76
P28: Terminated | Q28: 10543.32
P29: Grand Total | Q29: 218867.16
G38: Count of Employee_ID | H38: Column Labels
G39: Row Labels | H39: Resigned | I39: Terminated | J39: Grand Total
G40: Average | H40: 229 | I40: 61 | J40: 290
G41: High | H41: 153 | I41: 34 | J41: 187
G42: Low | H42: 98 | I42: 26 | J42: 124
G43: Grand Total | H43: 480 | I43: 121 | J43: 601

Sheet Detail2
A1: Details for Sum of Performance_Score
A3: Employee_ID | B3: Employee_Name | C3: Department_name | D3: Department_ID | E3: Location_name | F3: Location_ID | G3: Job_Title | H3: Salary_Band | I3: Employment_Type | J3: Gender | K3: Age_Group | L3: Hire_Date | M3: Attendance_Rate_Percent | N3: Performance_Score | O3: Performance_Level | P3: Review_Status | Q3: Manager_Rating | R3: Training_Hours | S3: Attrition_status | T3: Exit_Date | U3: Manager_ID
A4: 303524 | B4: Layla Al Falasi | C4: Customer Support | D4: D07 | E4: Dubai | F4: L01 | G4: Sales Executive | H4: Band 4 | I4: Full-Time | J4: Female | K4: 20-29 | L4: 2023-02-20 | M4: 75.03 | N4: 59 | O4: Average | P4: Completed | Q4: 5 | R4: 13 | S4: Resigned | T4: 2024-12-27
A5: 303525 | B5: Ali Farooq | C5: Marketing | D5: D05 | E5: Abu Dhabi | F5: L02 | G5: HR Executive | H5: Band 3 | I5: Part-Time | J5: Male | K5: 50+ | L5: 2023-04-29 | M5: 78.82 | N5: 78 | O5: Average | P5: Pending | R5: 16 | S5: Resigned | T5: 2024-01-03
A6: 303527 | B6: Omar Menon | C6: Finance | D6: D03 | E6: Dubai | F6: L01 | G6: Software Engineer | H6: Band 3 | I6: Full-Time | J6: Male | K6: 50+ | L6: 2021-07-13 | M6: 91.05 | N6: 73 | O6: Average | P6: Completed | Q6: 4 | R6: 8 | S6: Active
A7: 303529 | B7: Ahmed Gupta | C7: IT | D7: D04 | E7: Ajman | F7: L04 | G7: HR Executive | H7: Band 1 | I7: Full-Time | J7: Female | K7: 40-49 | L7: 2023-10-07 | M7: 76.71 | N7: 62 | O7: Average | P7: Completed | Q7: 3 | R7: 32 | S7: Active
A8: 303530 | B8: Karim Aziz | C8: IT | D8: D04 | E8: Sharjah | F8: L03 | G8: HR Manager | H8: Band 3 | I8: Part-Time | J8: Male | K8: 20-29 | L8: 2022-04-04 | M8: 90.1 | N8: 88 | O8: Average | P8: Completed | Q8: 3 | S8: Active | U8: 303525
A9: 303534 | B9: Karim Al Falasi | C9: HR | D9: D02 | E9: Sharjah | F9: L03 | G9: HR Executive | H9: Band 3 | I9: Contract | J9: Female | K9: 50+ | L9: 2022-12-21 | M9: 99.87 | N9: 96 | O9: Average | P9: Pending | R9: 20 | S9: Active | U9: 303526
A10: 303538 | B10: Samir Nair | C10: Operations | D10: D06 | E10: Abu Dhabi | F10: L02 | G10: HR Manager | H10: Band 2 | I10: Full-Time | J10: Male | K10: 50+ | L10: 2021-12-17 | M10: 76.15 | N10: 75 | O10: Average | P10: Not Due | R10: 18 | S10: Resigned | T10: 2023-07-27 | U10: 303523
A11: 303543 | B11: Yusuf Joseph | C11: HR | D11: D02 | E11: Al Ain | F11: L05 | G11: Customer Support Agent | H11: Band 4 | I11: Part-Time | J11: Female | K11: 40-49 | L11: 2023-05-16 | M11: 82.84 | N11: 57 | O11: Average | P11: Pending | R11: 7 | S11: Active | U11: 303538
A12: 303544 | B12: Noor Fernandez | C12: Operations | D12: D06 | E12: Al Ain | F12: L05 | G12: HR Executive | H12: Band 2 | I12: Contract | J12: Male | K12: 20-29 | L12: 2023-01-12 | M12: 92.25 | N12: 73 | O12: Average | P12: Pending | R12: 11 | S12: Active | U12: 303525
A13: 303545 | B13: Samir Aziz | C13: Operations | D13: D06 | E13: Al Ain | F13: L05 | G13: Software Engineer | H13: Band 4 | I13: Contract | J13: Female | K13: 40-49 | L13: 2024-01-17 | M13: 76.69 | N13: 70 | O13: Average | P13: Pending | R13: 25 | S13: Active | U13: 303534
A14: 303548 | B14: Sara Sharma | C14: Customer Support | D14: D07 | E14: Al Ain | F14: L05 | G14: HR Manager | H14: Band 1 | I14: Contract | J14: Female | K14: 30-39 | L14: 2024-01-05 | M14: 77.91 | N14: 79 | O14: Average | P14: Not Due | R14: 5 | S14: Active | U14: 303544
A15: 303549 | B15: Nadia Gupta | C15: IT | D15: D04 | E15: Ajman | F15: L04 | G15: IT Support Engineer | H15: Band 2 | I15: Part-Time | J15: Male | K15: 30-39 | L15: 2022-02-05 | M15: 98.69 | N15: 96 | O15: Average | P15: Pending | R15: 15 | S15: Resigned | T15: 2024-06-27 | U15: 303521
A16: 303550 | B16: Mohammed Fernandez | C16: HR | D16: D02 | E16: Abu Dhabi | F16: L02 | G16: Finance Analyst | H16: Band 2 | I16: Contract | J16: Female | K16: 40-49 | L16: 2022-01-15 | M16: 97.86 | N16: 90 | O16: Average | P16: Completed | Q16: 4 | R16: 5 | S16: Terminated | T16: 2024-04-17 | U16: 303533
A17: 303551 | B17: Khalid Khan | C17: Operations | D17: D06 | E17: Ajman | F17: L04 | G17: Sales Manager | H17: Band 2 | I17: Contract | J17: Male | K17: 30-39 | L17: 2021-03-26 | M17: 97 | N17: 93 | O17: Average | P17: Completed | Q17: 3 | R17: 11 | S17: Resigned | T17: 2023-09-30 | U17: 303530
A18: 303552 | B18: Ali Khan | C18: Sales | D18: D01 | E18: Abu Dhabi | F18: L02 | G18: Customer Support Agent | H18: Band 2 | I18: Part-Time | J18: Male | K18: 40-49 | L18: 2021-12-13 | M18: 95.88 | N18: 92 | O18: Average | P18: Pending | R18: 7 | S18: Active | U18: 303527
A19: 303557 | B19: Omar Joseph | C19: Sales | D19: D01 | E19: Dubai | F19: L01 | G19: IT Support Engineer | H19: Band 1 | I19: Full-Time | J19: Female | K19: 30-39 | L19: 2023-04-09 | M19: 83.95 | N19: 51 | O19: Average | P19: Completed | Q19: 4 | R19: 30 | S19: Active | U19: 303551
A20: 303560 | B20: Imran Al Falasi | C20: Operations | D20: D06 | E20: Sharjah | F20: L03 | G20: IT Support Engineer | H20: Band 1 | I20: Contract | J20: Female | K20: 20-29 | L20: 2022-02-08 | M20: 84.76 | N20: 52 | O20: Average | P20: Completed | Q20: 5 | R20: 20 | S20: Active | U20: 303555
A21: 303562 | B21: Ali Fernandez | C21: HR | D21: D02 | E21: Ajman | F21: L04 | G21: Sales Manager | H21: Band 4 | I21: Part-Time | J21: Female | K21: 40-49 | L21: 2021-02-12 | M21: 96.15 | N21: 93 | O21: Average | P21: Not Due | R21: 13 | S21: Resigned | T21: 2023-11-02 | U21: 303550
A22: 303563 | B22: Fatima Haddad | C22: Operations | D22: D06 | E22: Sharjah | F22: L03 | G22: IT Support Engineer | H22: Band 2 | I22: Contract | J22: Male | K22: 50+ | L22: 2022-05-25 | M22: 75.31 | N22: 51 | O22: Average | P22: Completed | Q22: 5 | R22: 13 | S22: Active | U22: 303557
A23: 303564 | B23: Khalid Shaikh | C23: Customer Support | D23: D07 | E23: Dubai | F23: L01 | G23: Marketing Specialist | H23: Band 1 | I23: Contract | J23: Female | K23: 20-29 | L23: 2022-07-09 | M23: 98.92 | N23: 87 | O23: Average | P23: Completed | Q23: 2 | R23: 17 | S23: Active | U23: 303529
A24: 303566 | B24: Layla Rahman | C24: Sales | D24: D01 | E24: Dubai | F24: L01 | G24: IT Support Engineer | H24: Band 1 | I24: Contract | J24: Male | K24: 20-29 | L24: 2022-04-21 | M24: 82.59 | N24: 70 | O24: Average | P24: Completed | Q24: 2 | S24: Terminated | T24: 2024-09-29 | U24: 303552
A25: 303567 | B25: Mariam Al Mansoori | C25: Operations | D25: D06 | E25: Al Ain | F25: L05 | G25: Finance Analyst | H25: Band 3 | I25: Full-Time | J25: Male | K25: 50+ | L25: 2023-10-05 | M25: 81.64 | N25: 72 | O25: Average | P25: Not Due | R25: 14 | S25: Active | U25: 303550
A26: 303568 | B26: Mariam Al Falasi | C26: Operations | D26: D06 | E26: Dubai | F26: L01 | G26: Customer Support Manager | H26: Band 4 | I26: Part-Time | J26: Female | K26: 30-39 | L26: 2022-01-21 | M26: 97.78 | N26: 91 | O26: Average | P26: Not Due | R26: 38 | S26: Active | U26: 303560
A27: 303569 | B27: Mohammed Shaikh | C27: Marketing | D27: D05 | E27: Sharjah | F27: L03 | G27: Sales Manager | H27: Band 2 | I27: Full-Time | J27: Female | K27: 40-49 | L27: 2021-09-16 | M27: 96.07 | N27: 92 | O27: Average | P27: Completed | Q27: 3 | R27: 25 | S27: Active | U27: 303557
A28: 303570 | B28: Sara Fernandez | C28: Operations | D28: D06 | E28: Abu Dhabi | F28: L02 | G28: Customer Support Agent | H28: Band 4 | I28: Contract | J28: Female | K28: 30-39 | L28: 2021-06-01 | M28: 84.74 | N28: 52 | O28: Average | P28: Pending | R28: 13 | S28: Active | U28: 303525
A29: 303572 | B29: Aisha Al Mansoori | C29: Customer Support | D29: D07 | E29: Sharjah | F29: L03 | G29: Marketing Specialist | H29: Band 4 | I29: Part-Time | J29: Female | K29: 20-29 | L29: 2024-03-28 | M29: 97.35 | N29: 90 | O29: Average | P29: Completed | Q29: 2 | R29: 32 | S29: Active | U29: 303564
A30: 303573 | B30: Samir Al Falasi | C30: Finance | D30: D03 | E30: Dubai | F30: L01 | G30: HR Executive | H30: Band 1 | I30: Contract | J30: Male | K30: 40-49 | L30: 2022-05-23 | M30: 93.51 | N30: 73 | O30: Average | P30: Completed | Q30: 3 | R30: 10 | S30: Active | U30: 303526
A31: 303575 | B31: Fatima Hussain | C31: Customer Support | D31: D07 | E31: Sharjah | F31: L03 | G31: Accountant | H31: Band 2 | I31: Part-Time | J31: Male | K31: 50+ | L31: 2024-01-14 | M31: 97.36 | N31: 90 | O31: Average | P31: Completed | Q31: 5 | R31: 7 | S31: Terminated | T31: 2024-11-23 | U31: 303543
A32: 303578 | B32: Yusuf Haddad | C32: IT | D32: D04 | E32: Sharjah | F32: L03 | G32: Operations Coordinator | H32: Band 1 | I32: Full-Time | J32: Male | K32: 30-39 | L32: 2021-07-16 | M32: 88.17 | N32: 90 | O32: Average | P32: Completed | Q32: 4 | R32: 17 | S32: Resigned | T32: 2023-01-01 | U32: 303544
A33: 303579 | B33: Noor Al Mansoori | C33: IT | D33: D04 | E33: Ajman | F33: L04 | G33: Customer Support Agent | H33: Band 2 | I33: Contract | J33: Male | K33: 40-49 | L33: 2022-12-15 | M33: 79.2 | N33: 73 | O33: Average | P33: Not Due | R33: 15 | S33: Active | U33: 303563
A34: 303580 | B34: Samir Sharma | C34: Customer Support | D34: D07 | E34: Dubai | F34: L01 | G34: Finance Analyst | H34: Band 4 | I34: Full-Time | J34: Female | K34: 50+ | L34: 2021-08-03 | M34: 99.94 | N34: 97 | O34: Average | P34: Not Due | S34: Terminated | T34: 2022-02-06 | U34: 303559
A35: 303582 | B35: Mariam Gupta | C35: Finance | D35: D03 | E35: Sharjah | F35: L03 | G35: Sales Executive | H35: Band 1 | I35: Part-Time | J35: Male | K35: 30-39 | L35: 2021-06-22 | M35: 88.89 | N35: 82 | O35: Average | P35: Completed | Q35: 3 | R35: 33 | S35: Active | U35: 303529
A36: 303585 | B36: Yusuf D'Souza | C36: Marketing | D36: D05 | E36: Al Ain | F36: L05 | G36: Customer Support Manager | H36: Band 2 | I36: Part-Time | J36: Male | K36: 40-49 | L36: 2023-04-20 | M36: 81.39 | N36: 72 | O36: Average | P36: Completed | Q36: 2 | R36: 34 | S36: Active | U36: 303520
A37: 303586 | B37: Mariam Fernandez | C37: Marketing | D37: D05 | E37: Dubai | F37: L01 | G37: Finance Analyst | H37: Band 4 | I37: Contract | J37: Male | K37: 50+ | L37: 2024-02-21 | M37: 89.96 | N37: 88 | O37: Average | P37: Completed | Q37: 3 | R37: 24 | S37: Active | U37: 303539
A38: 303587 | B38: Yusuf Menon | C38: Finance | D38: D03 | E38: Al Ain | F38: L05 | G38: HR Executive | H38: Band 2 | I38: Full-Time | J38: Female | K38: 30-39 | L38: 2022-05-23 | M38: 83.31 | N38: 59 | O38: Average | P38: Pending | R38: 12 | S38: Active | U38: 303546
A39: 303588 | B39: Zaid Aziz | C39: Operations | D39: D06 | E39: Dubai | F39: L01 | G39: Accountant | H39: Band 4 | I39: Contract | J39: Female | K39: 20-29 | L39: 2022-11-04 | M39: 96.32 | N39: 87 | O39: Average | P39: Completed | Q39: 5 | R39: 38 | S39: Active | U39: 303534
A40: 303589 | B40: Samir Rahman | C40: Sales | D40: D01 | E40: Sharjah | F40: L03 | G40: Accountant | H40: Band 4 | I40: Full-Time | J40: Female | K40: 30-39 | L40: 2023-03-13 | M40: 82.1 | N40: 71 | O40: Average | P40: Not Due | R40: 17 | S40: Active | U40: 303552
A41: 303591 | B41: Layla Menon | C41: Customer Support | D41: D07 | E41: Sharjah | F41: L03 | G41: HR Executive | H41: Band 1 | I41: Contract | J41: Male | K41: 20-29 | L41: 2021-09-26 | M41: 80.17 | N41: 78 | O41: Average | P41: Completed | Q41: 4 | R41: 17 | S41: Active | U41: 303561
...

Sheet PIVOT TABLE
B4: Row Labels | C4: Count of Job_Title | D4: Row Labels | E4: Count of Employee_Name
B5: Customer Support | C5: 350 | D5: Female | E5: 1224
B6: Finance | C6: 342 | D6: Male | E6: 1276 | R6: Age_Group | S6: (All)
B7: HR | C7: 337 | D7: Grand Total | E7: 2500 | M7: Department_name | N7: (All)
B8: IT | C8: 375 | R8: Row Labels | S8: Count of Employee_Name
B9: Marketing | C9: 367 | M9: Row Labels | N9: Count of Performance_Level | R9: Accountant | S9: 204
B10: Operations | C10: 369 | D10: Row Labels | E10: Count of Employee_Name | M10: Band 1 | N10: 600 | R10: Customer Support Agent | S10: 211
B11: Sales | C11: 360 | D11: Abu Dhabi | E11: 495 | M11: Band 2 | N11: 647 | R11: Customer Support Manager | S11: 201
B12: Grand Total | C12: 2500 | D12: Ajman | E12: 482 | M12: Band 3 | N12: 597 | R12: Finance Analyst | S12: 213
D13: Al Ain | E13: 539 | M13: Band 4 | N13: 656 | R13: HR Executive | S13: 213
D14: Dubai | E14: 507 | M14: Grand Total | N14: 2500 | R14: HR Manager | S14: 190
B15: Row Labels | C15: Sum of Manager_Rating | D15: Sharjah | E15: 477 | R15: IT Support Engineer | S15: 207
B16: Customer Support | C16: 911 | D16: Grand Total | E16: 2500 | R16: Marketing Specialist | S16: 212
B17: Finance | C17: 842 | R17: Operations Coordinator | S17: 188
B18: HR | C18: 884 | D18: Row Labels | E18: Sum of Training_Hours | R18: Sales Executive | S18: 226
B19: IT | C19: 957 | D19: Average | E19: 24802 | R19: Sales Manager | S19: 215
B20: Marketing | C20: 938 | D20: High | E20: 14366 | J20: Row Labels | K20: Count of Department_name | R20: Software Engineer | S20: 220 | U20: Hire_Date | V20: (All)
B21: Operations | C21: 927 | D21: Low | E21: 10662 | J21: Active | K21: 1899 | R21: Grand Total | S21: 2500
B22: Sales | C22: 873 | D22: Grand Total | E22: 49830 | J22: Resigned | K22: 480 | U22: Row Labels | V22: Count of Gender
B23: Grand Total | C23: 6332 | J23: Terminated | K23: 121 | U23: Accountant | V23: 204
J24: Grand Total | K24: 2500 | O24: Row Labels | P24: Sum of Performance_Score | U24: Customer Support Agent | V24: 211
O25: Average | P25: 95685 | U25: Customer Support Manager | V25: 201
O26: High | P26: 61958 | U26: Finance Analyst | V26: 213
M27: Department_name | N27: (All) | O27: Low | P27: 33561 | U27: HR Executive | V27: 213
O28: Grand Total | P28: 191204 | U28: HR Manager | V28: 190
E29: Row Labels | F29: Sum of Employee_ID | M29: Row Labels | N29: Count of Job_Title | U29: IT Support Engineer | V29: 207
E30: Active | F30: 578759488 | M30: Active | N30: 1899 | U30: Marketing Specialist | V30: 212
E31: Resigned | F31: 146280776 | M31: Resigned | N31: 480 | U31: Operations Coordinator | V31: 188
E32: Terminated | F32: 36883486 | M32: Terminated | N32: 121 | U32: Sales Executive | V32: 226
E33: Grand Total | F33: 761923750 | M33: Grand Total | N33: 2500 | U33: Sales Manager | V33: 215
U34: Software Engineer | V34: 220
U35: Grand Total | V35: 2500
B36: Row Labels | C36: Average of Training_Hours
B37: Active | C37: 22.555622
B38: Resigned | C38: 22.340426
B39: Terminated | C39: 23.92233
B40: Grand Total | C40: 22.57816
B47: Row Labels | C47: Sum of Performance_Score | G47: Age_Group | H47: (All)
B48: Active | C48: 145324
B49: Resigned | C49: 36780 | G49: Row Labels | H49: Count of Employment_Type
...

Sheet male female count
A3: Row Labels | B3: Count of Gender
A4: Female | B4: 1224
A5: Male | B5: 1276
A6: Grand Total | B6: 2500

Sheet Locations
A1: Location_ID | B1: Office_Location
A2: L01 | B2: Dubai
A3: L02 | B3: Abu Dhabi
A4: L03 | B4: Sharjah
A5: L04 | B5: Ajman
A6: L05 | B6: Al Ain

Sheet DASHBOARD
